@generated
{
  "kind": "issue",
  "data": {
    "callable": "remote_code_execution.rce_problem",
    "callable_line": 1,
    "code": 5001,
    "line": 3,
    "start": 9,
    "end": 10,
    "filename": "remote_code_execution.py",
    "message":
      "Possible remote code execution due to [UserControlled] data reaching [RemoteCodeExecution] sink(s)",
    "traces": [
      {
        "name": "forward",
        "roots": [
          {
            "root": {
              "filename": "remote_code_execution.py",
              "line": 2,
              "start": 8,
              "end": 27
            },
            "leaves": [
              {
                "kind": "UserControlled",
                "name": "__user_controlled",
                "on_all_flows": true
              }
            ]
          }
        ]
      },
      {
        "name": "backward",
        "roots": [
          {
            "root": {
              "filename": "remote_code_execution.py",
              "line": 3,
              "start": 9,
              "end": 10
            },
            "leaves": [
              {
                "kind": "RemoteCodeExecution",
                "name": "eval",
                "on_all_flows": true
              }
            ]
          }
        ]
      }
    ]
  }
}
